
2016-05-12 10:57:45
Traceback (most recent call last):
  File "./json/decoder.py", line 368, in raw_decode
StopIteration

During handling of the above exception, another exception occurred:

Traceback (most recent call last):
  File "D:\sublime\sublime_plugin.py", line 533, in run_
    return self.run(**args)
  File "/Users/wbond/Library/Application Support/Sublime Text 3/Packages/SFTP/sftp/commands.py", line 3273, in run
  File "/Users/wbond/Library/Application Support/Sublime Text 3/Packages/SFTP/sftp/config.py", line 147, in parse_config
  File "./json/__init__.py", line 319, in loads
  File "./json/decoder.py", line 352, in decode
  File "./json/decoder.py", line 370, in raw_decode
ValueError: No JSON object could be decoded
2016-05-13 10:06:50
Traceback (most recent call last):
  File "/Users/wbond/Library/Application Support/Sublime Text 3/Packages/SFTP/sftp/file_transfer.py", line 355, in handle_get_dirs
  File "/Users/wbond/Library/Application Support/Sublime Text 3/Packages/SFTP/sftp/sftp_transport.py", line 380, in lcd
SFTP.sftp.errors.NotFoundError: Folder not found

During handling of the above exception, another exception occurred:

Traceback (most recent call last):
  File "/Users/wbond/Library/Application Support/Sublime Text 3/Packages/SFTP/sftp/threads.py", line 16, in run_with_except_hook
  File "/Users/wbond/Library/Application Support/Sublime Text 3/Packages/SFTP/sftp/threads.py", line 119, in handler
  File "/Users/wbond/Library/Application Support/Sublime Text 3/Packages/SFTP/sftp/commands.py", line 355, in run
  File "/Users/wbond/Library/Application Support/Sublime Text 3/Packages/SFTP/sftp/commands.py", line 510, in do_operation
  File "/Users/wbond/Library/Application Support/Sublime Text 3/Packages/SFTP/sftp/file_transfer.py", line 47, in handler
  File "/Users/wbond/Library/Application Support/Sublime Text 3/Packages/SFTP/sftp/sftp_transport.py", line 410, in get
  File "/Users/wbond/Library/Application Support/Sublime Text 3/Packages/SFTP/sftp/file_transfer.py", line 361, in handle_get_dirs
  File "/Users/wbond/Library/Application Support/Sublime Text 3/Packages/SFTP/sftp/sftp_transport.py", line 380, in lcd
SFTP.sftp.errors.NotFoundError: Folder not found
2016-05-17 10:41:53
Traceback (most recent call last):
  File "/Users/wbond/Library/Application Support/Sublime Text 3/Packages/SFTP/sftp/file_transfer.py", line 394, in handle_put_dirs
  File "/Users/wbond/Library/Application Support/Sublime Text 3/Packages/SFTP/sftp/sftp_transport.py", line 366, in cd
SFTP.sftp.errors.NotFoundError: Folder not found

During handling of the above exception, another exception occurred:

Traceback (most recent call last):
  File "/Users/wbond/Library/Application Support/Sublime Text 3/Packages/SFTP/sftp/threads.py", line 16, in run_with_except_hook
  File "/Users/wbond/Library/Application Support/Sublime Text 3/Packages/SFTP/sftp/threads.py", line 119, in handler
  File "/Users/wbond/Library/Application Support/Sublime Text 3/Packages/SFTP/sftp/commands.py", line 355, in run
  File "/Users/wbond/Library/Application Support/Sublime Text 3/Packages/SFTP/sftp/commands.py", line 510, in do_operation
  File "/Users/wbond/Library/Application Support/Sublime Text 3/Packages/SFTP/sftp/file_transfer.py", line 47, in handler
  File "/Users/wbond/Library/Application Support/Sublime Text 3/Packages/SFTP/sftp/sftp_transport.py", line 662, in put
  File "/Users/wbond/Library/Application Support/Sublime Text 3/Packages/SFTP/sftp/file_transfer.py", line 397, in handle_put_dirs
  File "/Users/wbond/Library/Application Support/Sublime Text 3/Packages/SFTP/sftp/sftp_transport.py", line 366, in cd
SFTP.sftp.errors.NotFoundError: Folder not found
